from django.core import exceptions
from django.contrib.auth import (
    authenticate, password_validation, get_user_model
)
from rest_framework import serializers


User = get_user_model()


class UserSerializer(serializers.ModelSerializer):

    class Meta:
        model = User
        fields = ('id', 'username', 'email')


class RegisterSerializer(serializers.ModelSerializer):
    class Meta:
        model = User
        fields = ('id', 'username', 'email', 'password')
        extra_kwargs = {'password': {'write_only': True}}

    def validate(self, data):
        # get the password from the data
        password = data.get('password')

        errors = {}
        try:
            # validate the password and catch the exception
            password_validation.validate_password(password=password, user=User)

        # the exception raised here is different than serializers.ValidationError
        except exceptions.ValidationError as e:
            errors['password'] = list(e.messages)

        if errors:
            raise serializers.ValidationError(errors)

        return super(RegisterSerializer, self).validate(data)

    def create(self, validated_data):
        username = validated_data['username']
        email = validated_data['email']
        password = validated_data['password']
        user = User.objects.create_user(username, email, password)
        return user


class LoginSerializer(serializers.Serializer):
    username = serializers.CharField()
    password = serializers.CharField()

    def validate(self, data):
        print(data)
        user = authenticate(**data)
        print(user)
        if user and user.is_active:
            return user
        raise serializers.ValidationError(
            "Make sure the username or the password are correct!"
        )
